Traceback (most recent call last):
  File "/opt/hostedtoolcache/Python/3.8.12/x64/lib/python3.8/site-packages/jupyter_cache/executors/utils.py", line 51, in single_nb_execution
    executenb(
  File "/opt/hostedtoolcache/Python/3.8.12/x64/lib/python3.8/site-packages/nbclient/client.py", line 1204, in execute
    return NotebookClient(nb=nb, resources=resources, km=km, **kwargs).execute()
  File "/opt/hostedtoolcache/Python/3.8.12/x64/lib/python3.8/site-packages/nbclient/util.py", line 84, in wrapped
    return just_run(coro(*args, **kwargs))
  File "/opt/hostedtoolcache/Python/3.8.12/x64/lib/python3.8/site-packages/nbclient/util.py", line 62, in just_run
    return loop.run_until_complete(coro)
  File "/opt/hostedtoolcache/Python/3.8.12/x64/lib/python3.8/asyncio/base_events.py", line 616, in run_until_complete
    return future.result()
  File "/opt/hostedtoolcache/Python/3.8.12/x64/lib/python3.8/site-packages/nbclient/client.py", line 663, in async_execute
    await self.async_execute_cell(
  File "/opt/hostedtoolcache/Python/3.8.12/x64/lib/python3.8/site-packages/nbclient/client.py", line 965, in async_execute_cell
    await self._check_raise_for_error(cell, cell_index, exec_reply)
  File "/opt/hostedtoolcache/Python/3.8.12/x64/lib/python3.8/site-packages/nbclient/client.py", line 862, in _check_raise_for_error
    raise CellExecutionError.from_cell_and_msg(cell, exec_reply_content)
nbclient.exceptions.CellExecutionError: An error occurred while executing the following cell:
------------------
fig = plt.figure()
ax = fig.gca()
X, y = df.sqfeet, df.rent
t = rtreeviz_univar(ax,
                    X, y,
                    max_depth=1,
                    feature_name='sqfeet',
                    target_name='rent',
                    fontsize=14)
plt.show()
------------------

[0;31m---------------------------------------------------------------------------[0m
[0;31mTypeError[0m                                 Traceback (most recent call last)
Input [0;32mIn [10][0m, in [0;36m<cell line: 4>[0;34m()[0m
[1;32m      2[0m ax [38;5;241m=[39m fig[38;5;241m.[39mgca()
[1;32m      3[0m X, y [38;5;241m=[39m df[38;5;241m.[39msqfeet, df[38;5;241m.[39mrent
[0;32m----> 4[0m t [38;5;241m=[39m [43mrtreeviz_univar[49m[43m([49m[43max[49m[43m,[49m
[1;32m      5[0m [43m                    [49m[43mX[49m[43m,[49m[43m [49m[43my[49m[43m,[49m
[1;32m      6[0m [43m                    [49m[43mmax_depth[49m[38;5;241;43m=[39;49m[38;5;241;43m1[39;49m[43m,[49m
[1;32m      7[0m [43m                    [49m[43mfeature_name[49m[38;5;241;43m=[39;49m[38;5;124;43m'[39;49m[38;5;124;43msqfeet[39;49m[38;5;124;43m'[39;49m[43m,[49m
[1;32m      8[0m [43m                    [49m[43mtarget_name[49m[38;5;241;43m=[39;49m[38;5;124;43m'[39;49m[38;5;124;43mrent[39;49m[38;5;124;43m'[39;49m[43m,[49m
[1;32m      9[0m [43m                    [49m[43mfontsize[49m[38;5;241;43m=[39;49m[38;5;241;43m14[39;49m[43m)[49m
[1;32m     10[0m plt[38;5;241m.[39mshow()

[0;31mTypeError[0m: rtreeviz_univar() got an unexpected keyword argument 'max_depth'
TypeError: rtreeviz_univar() got an unexpected keyword argument 'max_depth'

